<?xml version="1.0" ?>
<!-- =================================================================================== -->
<!-- |    This document was autogenerated by xacro from ./src/bifrank_description/urdf/bifrank_robot.urdf.xacro | -->
<!-- |    EDITING THIS FILE BY HAND IS NOT RECOMMENDED                                 | -->
<!-- =================================================================================== -->
<robot name="bifrank_robot">
  <!-- PARAMETERS -->
  <!-- <xacro:arg name="lewis_arm_id" default="lewis" /> -->
  <!-- <xacro:arg name="richard_arm_id" default="richard" /> -->
  <!-- For a multi arm setup, we need a threaded robot running async-->
  <!-- <xacro:arg name="multi_arm" default="true" /> -->
  
  <!-- ROBOT STRUCTURE -->
  <link name="world"/>
  <joint name="base_joint" type="revolute">
    <parent link="world"/>
    <child link="base_link"/>
    <origin rpy="0 0 0" xyz="0 0 0"/>
    <axis xyz="0 0 1"/>
    <limit effort="10.0" lower="-1.57" upper="1.57" velocity="2.0"/>
    <dynamics damping="0.1" friction="0.0"/>
  </joint>
  <!-- Define the base link -->
  <link name="base_link">
    <visual>
      <geometry>
        <box size="0.5 0.5 0.1"/>
      </geometry>
    </visual>
    <collision>
      <geometry>
        <box size="0.5 0.5 0.1"/>
      </geometry>
    </collision>
  </link>
  <!-- Fixed joint mounting the left FR3 (renamed “lewis”) to the base -->
  <link name="lewis_fr3_base">
  </link>
  <joint name="lewis_arm_mount" type="fixed">
    <parent link="base_link"/>
    <child link="lewis_fr3_base"/>
    <!-- Adjust xyz - rpy as needed -->
    <origin rpy="-0.9 0.177 -0.15" xyz="0.0 0.1 0.2"/>
  </joint>
  <!-- safety_distance Minimum safety distance in [m] by which the collision volumes are expanded and which is enforced during robot motions -->
  <!-- arm_id Namespace of the robot arm. Serves to differentiate between arms in case of multiple instances. -->
  <!-- joint_limits description of the joint limits that comes from a YAML file. Example definition ${xacro.load_yaml('$(find franka_description)/robots/fr3/joint_limits.yaml')} -->
  <!-- kinematics description of the kinematics that comes from a YAML file. Example definition ${xacro.load_yaml('$(find franka_description)/robots/fr3/kinematics.yaml')} -->
  <!-- inertials description of the inertials that comes from a YAML file. Example definition ${xacro.load_yaml('$(find franka_description)/robots/fr3/inertials.yaml')} -->
  <!-- dynamics description of the dynamics that comes from a YAML file. Example definition ${xacro.load_yaml('$(find franka_description)/robots/fr3/dynamics.yaml')} -->
  <!-- <xacro:property name="prefix" value="${arm_id + '_'}" /> -->
  <!-- sub-link defining detailed meshes for collision with environment -->
  <link name="lewis_fr3_link0">
    <visual name="lewis_fr3_link0_visual">
      <geometry>
        <mesh filename="package://model/meshes/visual/link0.dae"/>
      </geometry>
    </visual>
    <collision name="lewis_fr3_link0_collision">
      <geometry>
        <mesh filename="package://model/meshes/collision/link0.stl"/>
      </geometry>
    </collision>
    <inertial>
      <origin rpy="0.0 0.0 0.0" xyz="-0.0172 0.0004 0.0745"/>
      <mass value="2.3966"/>
      <inertia ixx="0.009" ixy="0.0" ixz="0.002" iyy="0.0115" iyz="0.0" izz="0.0085"/>
    </inertial>
  </link>
  <!-- sub-link defining detailed meshes for collision with environment -->
  <link name="lewis_fr3_link1">
    <visual name="lewis_fr3_link1_visual">
      <geometry>
        <mesh filename="package://model/meshes/visual/link1.dae"/>
      </geometry>
    </visual>
    <collision name="lewis_fr3_link1_collision">
      <geometry>
        <mesh filename="package://model/meshes/collision/link1.stl"/>
      </geometry>
    </collision>
    <inertial>
      <origin rpy="0.0 0.0 0.0" xyz="0.0000004128 -0.0181251324 -0.0386035970"/>
      <mass value="2.9274653454"/>
      <inertia ixx="0.023927316485107913" ixy="1.3317903455714081e-05" ixz="-0.00011404774918616684" iyy="0.0224821613275756" iyz="-0.0019950320628240115" izz="0.006350098258530016"/>
    </inertial>
  </link>
  <joint name="lewis_fr3_joint1" type="revolute">
    <origin rpy="0.0 0.0 0.0" xyz="0 0 0.333"/> <!-- 0 0 0.333 -->
    <parent link="lewis_fr3_link0"/>
    <child link="lewis_fr3_link1"/>
    <axis xyz="0 0 1"/>
    <limit effort="87.0" lower="-2.7437" upper="2.7437" velocity="2.62"/>
    <safety_controller k_position="100.0" k_velocity="40.0" soft_lower_limit="-2.7437" soft_upper_limit="2.7437"/>
    <dynamics D="1" K="7000" damping="0.003" friction="0.2" mu_coulomb="0" mu_viscous="16"/>
  </joint>
  <!-- sub-link defining detailed meshes for collision with environment -->
  <link name="lewis_fr3_link2">
    <visual name="lewis_fr3_link2_visual">
      <geometry>
        <mesh filename="package://model/meshes/visual/link2.dae"/>
      </geometry>
    </visual>
    <collision name="lewis_fr3_link2_collision">
      <geometry>
        <mesh filename="package://model/meshes/collision/link2.stl"/>
      </geometry>
    </collision>
    <inertial>
      <origin rpy="0.0 0.0 0.0" xyz="0.0031828864 -0.0743221644 0.0088146084"/>
      <mass value="2.935537"/> <!-- 2.9355370338 -->
      <inertia ixx="0.041938946257609425" ixy="0.00020257331521090626" ixz="0.004077784227179924" iyy="0.02514514885014724" iyz="-0.0042252158006570156" izz="0.06170214472888839"/>
    </inertial>
  </link>
  <joint name="lewis_fr3_joint2" type="revolute">
    <origin rpy="-1.570796326794897 0 0" xyz="0 0 0"/>
    <parent link="lewis_fr3_link1"/>
    <child link="lewis_fr3_link2"/>
    <axis xyz="0 0 1"/>
    <limit effort="87.0" lower="-1.7837" upper="1.7837" velocity="2.62"/>
    <safety_controller k_position="100.0" k_velocity="40.0" soft_lower_limit="-1.7837" soft_upper_limit="1.7837"/>
    <dynamics D="1" K="7000" damping="0.003" friction="0.2" mu_coulomb="0" mu_viscous="16"/>
  </joint>
  <!-- sub-link defining detailed meshes for collision with environment -->
  <link name="lewis_fr3_link3">
    <visual name="lewis_fr3_link3_visual">
      <geometry>
        <mesh filename="package://model/meshes/visual/link3.dae"/>
      </geometry>
    </visual>
    <collision name="lewis_fr3_link3_collision">
      <geometry>
        <mesh filename="package://model/meshes/collision/link3.stl"/>
      </geometry>
    </collision>
    <inertial>
      <origin rpy="0 0 0" xyz="0.0407015686 -0.0048200565 -0.0289730823"/>
      <mass value="2.2449013699"/>
      <inertia ixx="0.02410142547240885" ixy="0.002404694559042109" ixz="-0.002856269270114313" iyy="0.01974053266708178" iyz="-0.002104212683891874" izz="0.019044494482244823"/>
    </inertial>
  </link>
  <joint name="lewis_fr3_joint3" type="revolute">
    <origin rpy="1.570796326794897 0 0" xyz="0 -0.316 0"/>
    <parent link="lewis_fr3_link2"/>
    <child link="lewis_fr3_link3"/>
    <axis xyz="0 0 1"/>
    <limit effort="87.0" lower="-2.9007" upper="2.9007" velocity="2.62"/>
    <safety_controller k_position="100.0" k_velocity="40.0" soft_lower_limit="-2.9007" soft_upper_limit="2.9007"/>
    <dynamics D="1" K="7000" damping="0.003" friction="0.2" mu_coulomb="0" mu_viscous="16"/>
  </joint>
  <!-- sub-link defining detailed meshes for collision with environment -->
  <link name="lewis_fr3_link4">
    <visual name="lewis_fr3_link4_visual">
      <geometry>
        <mesh filename="package://model/meshes/visual/link4.dae"/>
      </geometry>
    </visual>
    <collision name="lewis_fr3_link4_collision">
      <geometry>
        <mesh filename="package://model/meshes/collision/link4.stl"/>
      </geometry>
    </collision>
    <inertial>
      <origin rpy="0 0 0" xyz="-0.0459100965 0.0630492960 -0.0085187868"/>
      <mass value="2.6155955791"/>
      <inertia ixx="0.03452998321913202" ixy="0.01322552265982813" ixz="0.01015142998484113" iyy="0.028881621933049058" iyz="-0.0009762833870704552" izz="0.04125471171146641"/>
    </inertial>
  </link>
  <joint name="lewis_fr3_joint4" type="revolute">
    <origin rpy="1.570796326794897 0 0" xyz="0.0825 0 0"/>
    <parent link="lewis_fr3_link3"/>
    <child link="lewis_fr3_link4"/>
    <axis xyz="0 0 1"/>
    <limit effort="87.0" lower="-3.0421" upper="-0.1518" velocity="2.62"/>
    <safety_controller k_position="100.0" k_velocity="40.0" soft_lower_limit="-3.0421" soft_upper_limit="-0.1518"/>
    <dynamics D="1" K="7000" damping="0.003" friction="0.2" mu_coulomb="0" mu_viscous="16"/>
  </joint>
  <!-- sub-link defining detailed meshes for collision with environment -->
  <link name="lewis_fr3_link5">
    <visual name="lewis_fr3_link5_visual">
      <geometry>
        <mesh filename="package://model/meshes/visual/link5.dae"/>
      </geometry>
    </visual>
    <collision name="lewis_fr3_link5_collision">
      <geometry>
        <mesh filename="package://model/meshes/collision/link5.stl"/>
      </geometry>
    </collision>
    <inertial>
      <origin rpy="0.0 0.0 0.0" xyz="-0.0016039605 0.0292536262 -0.0972965990"/>
      <mass value="2.3271207594"/>
      <inertia ixx="0.051610278463662895" ixy="-0.005715173387783472" ixz="-0.0035673167625872135" iyy="0.04787729713371481" iyz="0.010673985108535986" izz="0.016423625579357254"/>
    </inertial>
  </link>
  <joint name="lewis_fr3_joint5" type="revolute">
    <origin rpy="-1.570796326794897 0 0" xyz="-0.0825 0.384 0"/>
    <parent link="lewis_fr3_link4"/>
    <child link="lewis_fr3_link5"/>
    <axis xyz="0 0 1"/>
    <limit effort="12.0" lower="-2.8065" upper="2.8065" velocity="5.26"/>
    <safety_controller k_position="100.0" k_velocity="40.0" soft_lower_limit="-2.8065" soft_upper_limit="2.8065"/>
    <dynamics D="1" K="7000" damping="0.003" friction="0.2" mu_coulomb="0" mu_viscous="16"/>
  </joint>
  <!-- sub-link defining detailed meshes for collision with environment -->
  <link name="lewis_fr3_link6">
    <visual name="lewis_fr3_link6_visual">
      <geometry>
        <mesh filename="package://model/meshes/visual/link6.dae"/>
      </geometry>
    </visual>
    <collision name="lewis_fr3_link6_collision">
      <geometry>
        <mesh filename="package://model/meshes/collision/link6.stl"/>
      </geometry>
    </collision>
    <inertial>
      <origin rpy="0 0 0" xyz="0.0597131221 -0.0410294666 -0.0101692726"/>
      <mass value="1.8170376524"/>
      <inertia ixx="0.005412333594383447" ixy="0.006193456360285834" ixz="0.0014219289306117652" iyy="0.014058329545509979" iyz="-0.0013140753741120031" izz="0.016080817924212554"/>
    </inertial>
  </link>
  <joint name="lewis_fr3_joint6" type="revolute">
    <origin rpy="1.570796326794897 0 0" xyz="0 0 0"/>
    <parent link="lewis_fr3_link5"/>
    <child link="lewis_fr3_link6"/>
    <axis xyz="0 0 1"/>
    <limit effort="12.0" lower="0.5445" upper="4.5169" velocity="4.18"/>
    <safety_controller k_position="100.0" k_velocity="40.0" soft_lower_limit="0.5445" soft_upper_limit="4.5169"/>
    <dynamics D="1" K="7000" damping="0.003" friction="0.2" mu_coulomb="0" mu_viscous="16"/>
  </joint>
  <!-- sub-link defining detailed meshes for collision with environment -->
  <link name="lewis_fr3_link7">
    <visual name="lewis_fr3_link7_visual">
      <geometry>
        <mesh filename="package://model/meshes/visual/link7.dae"/>
      </geometry>
    </visual>
    <collision name="lewis_fr3_link7_collision">
      <geometry>
        <mesh filename="package://model/meshes/collision/link7.stl"/>
      </geometry>
    </collision>
    <inertial>
      <origin rpy="0 0 0" xyz="0.0045225817 0.0086261921 -0.0161633251"/>
      <mass value="0.6271432862"/>
      <inertia ixx="0.00021092389150104718" ixy="-2.433299114461931e-05" ixz="4.564480393778983e-05" iyy="0.00017718568002411474" iyz="8.744070223226438e-05" izz="5.993190599659971e-05"/>
    </inertial>
  </link>
  <joint name="lewis_fr3_joint7" type="revolute">
    <origin rpy="1.570796326794897 0 0" xyz="0.088 0 0"/>
    <parent link="lewis_fr3_link6"/>
    <child link="lewis_fr3_link7"/>
    <axis xyz="0 0 1"/>
    <limit effort="12.0" lower="-3.0159" upper="3.0159" velocity="5.26"/>
    <safety_controller k_position="100.0" k_velocity="40.0" soft_lower_limit="-3.0159" soft_upper_limit="3.0159"/>
    <dynamics D="1" K="7000" damping="0.003" friction="0.2" mu_coulomb="0" mu_viscous="16"/>
  </joint>
  <link name="lewis_fr3_link8"/>
  <joint name="lewis_fr3_joint8" type="fixed">
    <origin rpy="0 0 0" xyz="0 0 0.107"/> <!-- 0 0 0.107 -->
    <parent link="lewis_fr3_link7"/>
    <child link="lewis_fr3_link8"/>
  </joint>
  <!-- New end-effector -->
  <!-- <link name="${prefix}EE">
      <visual name="${prefix}EE_visual">
        <geometry>
          <mesh filename="package://${description_pkg}/meshes/robot_ee/${ee_id}/visual/EE.dae" />
        </geometry>
      </visual>
      <collision name="${prefix}EE_collision">
        <geometry>
          <mesh filename="package://franka_description/meshes/robot_ee/${ee_id}/collision/EE.stl" />
        </geometry>
      </collision>
      <xacro:ee-inertials name="EE" />
    </link> -->
  <!-- <joint name="${prefix}jointEE" type="fixed">
      <origin rpy="0.0 0.0 0.0" xyz="0.0 0.0 0.0" />
      <parent link="${prefix}link8" />
      <child link="${prefix}linkEE" />
    </joint> -->
  <!-- Gazebo requires a joint to a link called "world" for statically mounted robots -->
  <!-- <xacro:if value="${parent == 'world'}">
          <link name="${parent}" />
        </xacro:if> -->
  <!-- <link name="${parent}" /> -->
  <joint name="lewis_fr3_base_joint" type="fixed">
    <origin rpy="0 0 0" xyz="0 0 0"/>
    <parent link="lewis_fr3_base"/>
    <child link="lewis_fr3_link0"/>
  </joint>
  <gazebo reference="lewis_fr3_joint1">
    <!-- Needed for ODE to output external wrenches on joints -->
    <provideFeedback>true</provideFeedback>
  </gazebo>
  <transmission name="lewis_fr3_joint1_transmission">
    <type>transmission_interface/SimpleTransmission</type>
    <joint name="lewis_fr3_joint1">
      <hardwareInterface>hardware_interface/PositionJointInterface</hardwareInterface>
    </joint>
    <actuator name="lewis_fr3_joint1_motor">
      <hardwareInterface>hardware_interface/PositionJointInterface</hardwareInterface>
    </actuator>
  </transmission>
  <gazebo reference="lewis_fr3_joint2">
    <!-- Needed for ODE to output external wrenches on joints -->
    <provideFeedback>true</provideFeedback>
  </gazebo>
  <transmission name="lewis_fr3_joint2_transmission">
    <type>transmission_interface/SimpleTransmission</type>
    <joint name="lewis_fr3_joint2">
      <hardwareInterface>hardware_interface/PositionJointInterface</hardwareInterface>
    </joint>
    <actuator name="lewis_fr3_joint2_motor">
      <hardwareInterface>hardware_interface/PositionJointInterface</hardwareInterface>
    </actuator>
  </transmission>
  <gazebo reference="lewis_fr3_joint3">
    <!-- Needed for ODE to output external wrenches on joints -->
    <provideFeedback>true</provideFeedback>
  </gazebo>
  <transmission name="lewis_fr3_joint3_transmission">
    <type>transmission_interface/SimpleTransmission</type>
    <joint name="lewis_fr3_joint3">
      <hardwareInterface>hardware_interface/PositionJointInterface</hardwareInterface>
    </joint>
    <actuator name="lewis_fr3_joint3_motor">
      <hardwareInterface>hardware_interface/PositionJointInterface</hardwareInterface>
    </actuator>
  </transmission>
  <gazebo reference="lewis_fr3_joint4">
    <!-- Needed for ODE to output external wrenches on joints -->
    <provideFeedback>true</provideFeedback>
  </gazebo>
  <transmission name="lewis_fr3_joint4_transmission">
    <type>transmission_interface/SimpleTransmission</type>
    <joint name="lewis_fr3_joint4">
      <hardwareInterface>hardware_interface/PositionJointInterface</hardwareInterface>
    </joint>
    <actuator name="lewis_fr3_joint4_motor">
      <hardwareInterface>hardware_interface/PositionJointInterface</hardwareInterface>
    </actuator>
  </transmission>
  <gazebo reference="lewis_fr3_joint5">
    <!-- Needed for ODE to output external wrenches on joints -->
    <provideFeedback>true</provideFeedback>
  </gazebo>
  <transmission name="lewis_fr3_joint5_transmission">
    <type>transmission_interface/SimpleTransmission</type>
    <joint name="lewis_fr3_joint5">
      <hardwareInterface>hardware_interface/PositionJointInterface</hardwareInterface>
    </joint>
    <actuator name="lewis_fr3_joint5_motor">
      <hardwareInterface>hardware_interface/PositionJointInterface</hardwareInterface>
    </actuator>
  </transmission>
  <gazebo reference="lewis_fr3_joint6">
    <!-- Needed for ODE to output external wrenches on joints -->
    <provideFeedback>true</provideFeedback>
  </gazebo>
  <transmission name="lewis_fr3_joint6_transmission">
    <type>transmission_interface/SimpleTransmission</type>
    <joint name="lewis_fr3_joint6">
      <hardwareInterface>hardware_interface/PositionJointInterface</hardwareInterface>
    </joint>
    <actuator name="lewis_fr3_joint6_motor">
      <hardwareInterface>hardware_interface/PositionJointInterface</hardwareInterface>
    </actuator>
  </transmission>
  <gazebo reference="lewis_fr3_joint7">
    <!-- Needed for ODE to output external wrenches on joints -->
    <provideFeedback>true</provideFeedback>
  </gazebo>
  <transmission name="lewis_fr3_joint7_transmission">
    <type>transmission_interface/SimpleTransmission</type>
    <joint name="lewis_fr3_joint7">
      <hardwareInterface>hardware_interface/PositionJointInterface</hardwareInterface>
    </joint>
    <actuator name="lewis_fr3_joint7_motor">
      <hardwareInterface>hardware_interface/PositionJointInterface</hardwareInterface>
    </actuator>
  </transmission>
  <gazebo reference="lewis_fr3_joint1">
    <!-- Needed for ODE to output external wrenches on joints -->
    <provideFeedback>true</provideFeedback>
  </gazebo>
  <transmission name="lewis_fr3_joint1_transmission">
    <type>transmission_interface/SimpleTransmission</type>
    <joint name="lewis_fr3_joint1">
      <hardwareInterface>hardware_interface/VelocityJointInterface</hardwareInterface>
    </joint>
    <actuator name="lewis_fr3_joint1_motor">
      <hardwareInterface>hardware_interface/VelocityJointInterface</hardwareInterface>
    </actuator>
  </transmission>
  <gazebo reference="lewis_fr3_joint2">
    <!-- Needed for ODE to output external wrenches on joints -->
    <provideFeedback>true</provideFeedback>
  </gazebo>
  <transmission name="lewis_fr3_joint2_transmission">
    <type>transmission_interface/SimpleTransmission</type>
    <joint name="lewis_fr3_joint2">
      <hardwareInterface>hardware_interface/VelocityJointInterface</hardwareInterface>
    </joint>
    <actuator name="lewis_fr3_joint2_motor">
      <hardwareInterface>hardware_interface/VelocityJointInterface</hardwareInterface>
    </actuator>
  </transmission>
  <gazebo reference="lewis_fr3_joint3">
    <!-- Needed for ODE to output external wrenches on joints -->
    <provideFeedback>true</provideFeedback>
  </gazebo>
  <transmission name="lewis_fr3_joint3_transmission">
    <type>transmission_interface/SimpleTransmission</type>
    <joint name="lewis_fr3_joint3">
      <hardwareInterface>hardware_interface/VelocityJointInterface</hardwareInterface>
    </joint>
    <actuator name="lewis_fr3_joint3_motor">
      <hardwareInterface>hardware_interface/VelocityJointInterface</hardwareInterface>
    </actuator>
  </transmission>
  <gazebo reference="lewis_fr3_joint4">
    <!-- Needed for ODE to output external wrenches on joints -->
    <provideFeedback>true</provideFeedback>
  </gazebo>
  <transmission name="lewis_fr3_joint4_transmission">
    <type>transmission_interface/SimpleTransmission</type>
    <joint name="lewis_fr3_joint4">
      <hardwareInterface>hardware_interface/VelocityJointInterface</hardwareInterface>
    </joint>
    <actuator name="lewis_fr3_joint4_motor">
      <hardwareInterface>hardware_interface/VelocityJointInterface</hardwareInterface>
    </actuator>
  </transmission>
  <gazebo reference="lewis_fr3_joint5">
    <!-- Needed for ODE to output external wrenches on joints -->
    <provideFeedback>true</provideFeedback>
  </gazebo>
  <transmission name="lewis_fr3_joint5_transmission">
    <type>transmission_interface/SimpleTransmission</type>
    <joint name="lewis_fr3_joint5">
      <hardwareInterface>hardware_interface/VelocityJointInterface</hardwareInterface>
    </joint>
    <actuator name="lewis_fr3_joint5_motor">
      <hardwareInterface>hardware_interface/VelocityJointInterface</hardwareInterface>
    </actuator>
  </transmission>
  <gazebo reference="lewis_fr3_joint6">
    <!-- Needed for ODE to output external wrenches on joints -->
    <provideFeedback>true</provideFeedback>
  </gazebo>
  <transmission name="lewis_fr3_joint6_transmission">
    <type>transmission_interface/SimpleTransmission</type>
    <joint name="lewis_fr3_joint6">
      <hardwareInterface>hardware_interface/VelocityJointInterface</hardwareInterface>
    </joint>
    <actuator name="lewis_fr3_joint6_motor">
      <hardwareInterface>hardware_interface/VelocityJointInterface</hardwareInterface>
    </actuator>
  </transmission>
  <gazebo reference="lewis_fr3_joint7">
    <!-- Needed for ODE to output external wrenches on joints -->
    <provideFeedback>true</provideFeedback>
  </gazebo>
  <transmission name="lewis_fr3_joint7_transmission">
    <type>transmission_interface/SimpleTransmission</type>
    <joint name="lewis_fr3_joint7">
      <hardwareInterface>hardware_interface/VelocityJointInterface</hardwareInterface>
    </joint>
    <actuator name="lewis_fr3_joint7_motor">
      <hardwareInterface>hardware_interface/VelocityJointInterface</hardwareInterface>
    </actuator>
  </transmission>
  <gazebo reference="lewis_fr3_joint1">
    <!-- Needed for ODE to output external wrenches on joints -->
    <provideFeedback>true</provideFeedback>
  </gazebo>
  <transmission name="lewis_fr3_joint1_transmission">
    <type>transmission_interface/SimpleTransmission</type>
    <joint name="lewis_fr3_joint1">
      <hardwareInterface>hardware_interface/EffortJointInterface</hardwareInterface>
    </joint>
    <actuator name="lewis_fr3_joint1_motor">
      <hardwareInterface>hardware_interface/EffortJointInterface</hardwareInterface>
    </actuator>
  </transmission>
  <gazebo reference="lewis_fr3_joint2">
    <!-- Needed for ODE to output external wrenches on joints -->
    <provideFeedback>true</provideFeedback>
  </gazebo>
  <transmission name="lewis_fr3_joint2_transmission">
    <type>transmission_interface/SimpleTransmission</type>
    <joint name="lewis_fr3_joint2">
      <hardwareInterface>hardware_interface/EffortJointInterface</hardwareInterface>
    </joint>
    <actuator name="lewis_fr3_joint2_motor">
      <hardwareInterface>hardware_interface/EffortJointInterface</hardwareInterface>
    </actuator>
  </transmission>
  <gazebo reference="lewis_fr3_joint3">
    <!-- Needed for ODE to output external wrenches on joints -->
    <provideFeedback>true</provideFeedback>
  </gazebo>
  <transmission name="lewis_fr3_joint3_transmission">
    <type>transmission_interface/SimpleTransmission</type>
    <joint name="lewis_fr3_joint3">
      <hardwareInterface>hardware_interface/EffortJointInterface</hardwareInterface>
    </joint>
    <actuator name="lewis_fr3_joint3_motor">
      <hardwareInterface>hardware_interface/EffortJointInterface</hardwareInterface>
    </actuator>
  </transmission>
  <gazebo reference="lewis_fr3_joint4">
    <!-- Needed for ODE to output external wrenches on joints -->
    <provideFeedback>true</provideFeedback>
  </gazebo>
  <transmission name="lewis_fr3_joint4_transmission">
    <type>transmission_interface/SimpleTransmission</type>
    <joint name="lewis_fr3_joint4">
      <hardwareInterface>hardware_interface/EffortJointInterface</hardwareInterface>
    </joint>
    <actuator name="lewis_fr3_joint4_motor">
      <hardwareInterface>hardware_interface/EffortJointInterface</hardwareInterface>
    </actuator>
  </transmission>
  <gazebo reference="lewis_fr3_joint5">
    <!-- Needed for ODE to output external wrenches on joints -->
    <provideFeedback>true</provideFeedback>
  </gazebo>
  <transmission name="lewis_fr3_joint5_transmission">
    <type>transmission_interface/SimpleTransmission</type>
    <joint name="lewis_fr3_joint5">
      <hardwareInterface>hardware_interface/EffortJointInterface</hardwareInterface>
    </joint>
    <actuator name="lewis_fr3_joint5_motor">
      <hardwareInterface>hardware_interface/EffortJointInterface</hardwareInterface>
    </actuator>
  </transmission>
  <gazebo reference="lewis_fr3_joint6">
    <!-- Needed for ODE to output external wrenches on joints -->
    <provideFeedback>true</provideFeedback>
  </gazebo>
  <transmission name="lewis_fr3_joint6_transmission">
    <type>transmission_interface/SimpleTransmission</type>
    <joint name="lewis_fr3_joint6">
      <hardwareInterface>hardware_interface/EffortJointInterface</hardwareInterface>
    </joint>
    <actuator name="lewis_fr3_joint6_motor">
      <hardwareInterface>hardware_interface/EffortJointInterface</hardwareInterface>
    </actuator>
  </transmission>
  <gazebo reference="lewis_fr3_joint7">
    <!-- Needed for ODE to output external wrenches on joints -->
    <provideFeedback>true</provideFeedback>
  </gazebo>
  <transmission name="lewis_fr3_joint7_transmission">
    <type>transmission_interface/SimpleTransmission</type>
    <joint name="lewis_fr3_joint7">
      <hardwareInterface>hardware_interface/EffortJointInterface</hardwareInterface>
    </joint>
    <actuator name="lewis_fr3_joint7_motor">
      <hardwareInterface>hardware_interface/EffortJointInterface</hardwareInterface>
    </actuator>
  </transmission>
  <transmission name="lewislewis_fr3__franka_state">
    <type>franka_hw/FrankaStateInterface</type>
    <joint name="lewislewis_fr3__joint1">
      <hardwareInterface>franka_hw/FrankaStateInterface</hardwareInterface>
    </joint>
    <joint name="lewislewis_fr3__joint2">
      <hardwareInterface>franka_hw/FrankaStateInterface</hardwareInterface>
    </joint>
    <joint name="lewislewis_fr3__joint3">
      <hardwareInterface>franka_hw/FrankaStateInterface</hardwareInterface>
    </joint>
    <joint name="lewislewis_fr3__joint4">
      <hardwareInterface>franka_hw/FrankaStateInterface</hardwareInterface>
    </joint>
    <joint name="lewislewis_fr3__joint5">
      <hardwareInterface>franka_hw/FrankaStateInterface</hardwareInterface>
    </joint>
    <joint name="lewislewis_fr3__joint6">
      <hardwareInterface>franka_hw/FrankaStateInterface</hardwareInterface>
    </joint>
    <joint name="lewislewis_fr3__joint7">
      <hardwareInterface>franka_hw/FrankaStateInterface</hardwareInterface>
    </joint>
    <actuator name="lewislewis_fr3__motor1">
      <hardwareInterface>franka_hw/FrankaStateInterface</hardwareInterface>
    </actuator>
    <actuator name="lewislewis_fr3__motor2">
      <hardwareInterface>franka_hw/FrankaStateInterface</hardwareInterface>
    </actuator>
    <actuator name="lewislewis_fr3__motor3">
      <hardwareInterface>franka_hw/FrankaStateInterface</hardwareInterface>
    </actuator>
    <actuator name="lewislewis_fr3__motor4">
      <hardwareInterface>franka_hw/FrankaStateInterface</hardwareInterface>
    </actuator>
    <actuator name="lewislewis_fr3__motor5">
      <hardwareInterface>franka_hw/FrankaStateInterface</hardwareInterface>
    </actuator>
    <actuator name="lewislewis_fr3__motor6">
      <hardwareInterface>franka_hw/FrankaStateInterface</hardwareInterface>
    </actuator>
    <actuator name="lewislewis_fr3__motor7">
      <hardwareInterface>franka_hw/FrankaStateInterface</hardwareInterface>
    </actuator>
  </transmission>
  <transmission name="lewislewis_fr3__franka_model">
    <type>franka_hw/FrankaModelInterface</type>
    <joint name="lewis_fr3_joint1">
      <role>root</role>
      <hardwareInterface>franka_hw/FrankaModelInterface</hardwareInterface>
    </joint>
    <joint name="lewis_fr3_joint8">
      <role>tip</role>
      <hardwareInterface>franka_hw/FrankaModelInterface</hardwareInterface>
    </joint>
    <actuator name="lewis_fr3_joint1_motor_root">
      <hardwareInterface>franka_hw/FrankaModelInterface</hardwareInterface>
    </actuator>
    <actuator name="lewis_fr3_joint8_motor_tip">
      <hardwareInterface>franka_hw/FrankaModelInterface</hardwareInterface>
    </actuator>
  </transmission>
  <!-- Fixed joint mounting the right FR3 (renamed “richard”) to the base -->
  <link name="richard_fr3_base"/>
  <joint name="richard_arm_mount" type="fixed">
    <parent link="base_link"/>
    <child link="richard_fr3_base"/>
    <!-- Adjust xyz - rpy as needed -->
    <origin rpy="0.9 0.177 0.15" xyz="0.0 -0.1 0.2"/>
  </joint>
  <!-- safety_distance Minimum safety distance in [m] by which the collision volumes are expanded and which is enforced during robot motions -->
  <!-- arm_id Namespace of the robot arm. Serves to differentiate between arms in case of multiple instances. -->
  <!-- joint_limits description of the joint limits that comes from a YAML file. Example definition ${xacro.load_yaml('$(find franka_description)/robots/fr3/joint_limits.yaml')} -->
  <!-- kinematics description of the kinematics that comes from a YAML file. Example definition ${xacro.load_yaml('$(find franka_description)/robots/fr3/kinematics.yaml')} -->
  <!-- inertials description of the inertials that comes from a YAML file. Example definition ${xacro.load_yaml('$(find franka_description)/robots/fr3/inertials.yaml')} -->
  <!-- dynamics description of the dynamics that comes from a YAML file. Example definition ${xacro.load_yaml('$(find franka_description)/robots/fr3/dynamics.yaml')} -->
  <!-- <xacro:property name="prefix" value="${arm_id + '_'}" /> -->
  <!-- sub-link defining detailed meshes for collision with environment -->
  <link name="richard_fr3_link0">
    <visual name="richard_fr3_link0_visual">
      <geometry>
        <mesh filename="package://model/meshes/visual/link0.dae"/>
      </geometry>
    </visual>
    <collision name="richard_fr3_link0_collision">
      <geometry>
        <mesh filename="package://model/meshes/collision/link0.stl"/>
      </geometry>
    </collision>
    <inertial>
      <origin rpy="0.0 0.0 0.0" xyz="-0.0172 0.0004 0.0745"/>
      <mass value="2.3966"/>
      <inertia ixx="0.009" ixy="0.0" ixz="0.002" iyy="0.0115" iyz="0.0" izz="0.0085"/>
    </inertial>
  </link>
  <!-- sub-link defining detailed meshes for collision with environment -->
  <link name="richard_fr3_link1">
    <visual name="richard_fr3_link1_visual">
      <geometry>
        <mesh filename="package://model/meshes/visual/link1.dae"/>
      </geometry>
    </visual>
    <collision name="richard_fr3_link1_collision">
      <geometry>
        <mesh filename="package://model/meshes/collision/link1.stl"/>
      </geometry>
    </collision>
    <inertial>
      <origin rpy="0 0 0" xyz="0.0000004128 -0.0181251324 -0.0386035970"/>
      <mass value="2.9274653454"/>
      <inertia ixx="0.023927316485107913" ixy="1.3317903455714081e-05" ixz="-0.00011404774918616684" iyy="0.0224821613275756" iyz="-0.0019950320628240115" izz="0.006350098258530016"/>
    </inertial>
  </link>
  <joint name="richard_fr3_joint1" type="revolute">
    <origin rpy="0 0 0" xyz="0 0 0.333"/>
    <parent link="richard_fr3_link0"/>
    <child link="richard_fr3_link1"/>
    <axis xyz="0 0 1"/>
    <limit effort="87.0" lower="-2.7437" upper="2.7437" velocity="2.62"/>
    <safety_controller k_position="100.0" k_velocity="40.0" soft_lower_limit="-2.7437" soft_upper_limit="2.7437"/>
    <dynamics D="1" K="7000" damping="0.003" friction="0.2" mu_coulomb="0" mu_viscous="16"/>
  </joint>
  <!-- sub-link defining detailed meshes for collision with environment -->
  <link name="richard_fr3_link2">
    <visual name="richard_fr3_link2_visual">
      <geometry>
        <mesh filename="package://model/meshes/visual/link2.dae"/>
      </geometry>
    </visual>
    <collision name="richard_fr3_link2_collision">
      <geometry>
        <mesh filename="package://model/meshes/collision/link2.stl"/>
      </geometry>
    </collision>
    <inertial>
      <origin rpy="0 0 0" xyz="0.0031828864 -0.0743221644 0.0088146084"/>
      <mass value="2.9355370338"/>
      <inertia ixx="0.041938946257609425" ixy="0.00020257331521090626" ixz="0.004077784227179924" iyy="0.02514514885014724" iyz="-0.0042252158006570156" izz="0.06170214472888839"/>
    </inertial>
  </link>
  <joint name="richard_fr3_joint2" type="revolute">
    <origin rpy="-1.570796326794897 0 0" xyz="0 0 0"/>
    <parent link="richard_fr3_link1"/>
    <child link="richard_fr3_link2"/>
    <axis xyz="0 0 1"/>
    <limit effort="87.0" lower="-1.7837" upper="1.7837" velocity="2.62"/>
    <safety_controller k_position="100.0" k_velocity="40.0" soft_lower_limit="-1.7837" soft_upper_limit="1.7837"/>
    <dynamics D="1" K="7000" damping="0.003" friction="0.2" mu_coulomb="0" mu_viscous="16"/>
  </joint>
  <!-- sub-link defining detailed meshes for collision with environment -->
  <link name="richard_fr3_link3">
    <visual name="richard_fr3_link3_visual">
      <geometry>
        <mesh filename="package://model/meshes/visual/link3.dae"/>
      </geometry>
    </visual>
    <collision name="richard_fr3_link3_collision">
      <geometry>
        <mesh filename="package://model/meshes/collision/link3.stl"/>
      </geometry>
    </collision>
    <inertial>
      <origin rpy="0 0 0" xyz="0.0407015686 -0.0048200565 -0.0289730823"/>
      <mass value="2.2449013699"/>
      <inertia ixx="0.02410142547240885" ixy="0.002404694559042109" ixz="-0.002856269270114313" iyy="0.01974053266708178" iyz="-0.002104212683891874" izz="0.019044494482244823"/>
    </inertial>
  </link>
  <joint name="richard_fr3_joint3" type="revolute">
    <origin rpy="1.570796326794897 0 0" xyz="0 -0.316 0"/>
    <parent link="richard_fr3_link2"/>
    <child link="richard_fr3_link3"/>
    <axis xyz="0 0 1"/>
    <limit effort="87.0" lower="-2.9007" upper="2.9007" velocity="2.62"/>
    <safety_controller k_position="100.0" k_velocity="40.0" soft_lower_limit="-2.9007" soft_upper_limit="2.9007"/>
    <dynamics D="1" K="7000" damping="0.003" friction="0.2" mu_coulomb="0" mu_viscous="16"/>
  </joint>
  <!-- sub-link defining detailed meshes for collision with environment -->
  <link name="richard_fr3_link4">
    <visual name="richard_fr3_link4_visual">
      <geometry>
        <mesh filename="package://model/meshes/visual/link4.dae"/>
      </geometry>
    </visual>
    <collision name="richard_fr3_link4_collision">
      <geometry>
        <mesh filename="package://model/meshes/collision/link4.stl"/>
      </geometry>
    </collision>
    <inertial>
      <origin rpy="0 0 0" xyz="-0.0459100965 0.0630492960 -0.0085187868"/>
      <mass value="2.6155955791"/>
      <inertia ixx="0.03452998321913202" ixy="0.01322552265982813" ixz="0.01015142998484113" iyy="0.028881621933049058" iyz="-0.0009762833870704552" izz="0.04125471171146641"/>
    </inertial>
  </link>
  <joint name="richard_fr3_joint4" type="revolute">
    <origin rpy="1.570796326794897 0 0" xyz="0.0825 0 0"/>
    <parent link="richard_fr3_link3"/>
    <child link="richard_fr3_link4"/>
    <axis xyz="0 0 1"/>
    <limit effort="87.0" lower="-3.0421" upper="-0.1518" velocity="2.62"/>
    <safety_controller k_position="100.0" k_velocity="40.0" soft_lower_limit="-3.0421" soft_upper_limit="-0.1518"/>
    <dynamics D="1" K="7000" damping="0.003" friction="0.2" mu_coulomb="0" mu_viscous="16"/>
  </joint>
  <!-- sub-link defining detailed meshes for collision with environment -->
  <link name="richard_fr3_link5">
    <visual name="richard_fr3_link5_visual">
      <geometry>
        <mesh filename="package://model/meshes/visual/link5.dae"/>
      </geometry>
    </visual>
    <collision name="richard_fr3_link5_collision">
      <geometry>
        <mesh filename="package://model/meshes/collision/link5.stl"/>
      </geometry>
    </collision>
    <inertial>
      <origin rpy="0 0 0" xyz="-0.0016039605 0.0292536262 -0.0972965990"/>
      <mass value="2.3271207594"/>
      <inertia ixx="0.051610278463662895" ixy="-0.005715173387783472" ixz="-0.0035673167625872135" iyy="0.04787729713371481" iyz="0.010673985108535986" izz="0.016423625579357254"/>
    </inertial>
  </link>
  <joint name="richard_fr3_joint5" type="revolute">
    <origin rpy="-1.570796326794897 0 0" xyz="-0.0825 0.384 0"/>
    <parent link="richard_fr3_link4"/>
    <child link="richard_fr3_link5"/>
    <axis xyz="0 0 1"/>
    <limit effort="12.0" lower="-2.8065" upper="2.8065" velocity="5.26"/>
    <safety_controller k_position="100.0" k_velocity="40.0" soft_lower_limit="-2.8065" soft_upper_limit="2.8065"/>
    <dynamics D="1" K="7000" damping="0.003" friction="0.2" mu_coulomb="0" mu_viscous="16"/>
  </joint>
  <!-- sub-link defining detailed meshes for collision with environment -->
  <link name="richard_fr3_link6">
    <visual name="richard_fr3_link6_visual">
      <geometry>
        <mesh filename="package://model/meshes/visual/link6.dae"/>
      </geometry>
    </visual>
    <collision name="richard_fr3_link6_collision">
      <geometry>
        <mesh filename="package://model/meshes/collision/link6.stl"/>
      </geometry>
    </collision>
    <inertial>
      <origin rpy="0 0 0" xyz="0.0597131221 -0.0410294666 -0.0101692726"/>
      <mass value="1.8170376524"/>
      <inertia ixx="0.005412333594383447" ixy="0.006193456360285834" ixz="0.0014219289306117652" iyy="0.014058329545509979" iyz="-0.0013140753741120031" izz="0.016080817924212554"/>
    </inertial>
  </link>
  <joint name="richard_fr3_joint6" type="revolute">
    <origin rpy="1.570796326794897 0 0" xyz="0 0 0"/>
    <parent link="richard_fr3_link5"/>
    <child link="richard_fr3_link6"/>
    <axis xyz="0 0 1"/>
    <limit effort="12.0" lower="0.5445" upper="4.5169" velocity="4.18"/>
    <safety_controller k_position="100.0" k_velocity="40.0" soft_lower_limit="0.5445" soft_upper_limit="4.5169"/>
    <dynamics D="1" K="7000" damping="0.003" friction="0.2" mu_coulomb="0" mu_viscous="16"/>
  </joint>
  <!-- sub-link defining detailed meshes for collision with environment -->
  <link name="richard_fr3_link7">
    <visual name="richard_fr3_link7_visual">
      <geometry>
        <mesh filename="package://model/meshes/visual/link7.dae"/>
      </geometry>
    </visual>
    <collision name="richard_fr3_link7_collision">
      <geometry>
        <mesh filename="package://model/meshes/collision/link7.stl"/>
      </geometry>
    </collision>
    <inertial>
      <origin rpy="0 0 0" xyz="0.0045225817 0.0086261921 -0.0161633251"/>
      <mass value="0.6271432862"/>
      <inertia ixx="0.00021092389150104718" ixy="-2.433299114461931e-05" ixz="4.564480393778983e-05" iyy="0.00017718568002411474" iyz="8.744070223226438e-05" izz="5.993190599659971e-05"/>
    </inertial>
  </link>
  <joint name="richard_fr3_joint7" type="revolute">
    <origin rpy="1.570796326794897 0 0" xyz="0.088 0 0"/>
    <parent link="richard_fr3_link6"/>
    <child link="richard_fr3_link7"/>
    <axis xyz="0 0 1"/>
    <limit effort="12.0" lower="-3.0159" upper="3.0159" velocity="5.26"/>
    <safety_controller k_position="100.0" k_velocity="40.0" soft_lower_limit="-3.0159" soft_upper_limit="3.0159"/>
    <dynamics D="1" K="7000" damping="0.003" friction="0.2" mu_coulomb="0" mu_viscous="16"/>
  </joint>
  <link name="richard_fr3_link8"/>
  <joint name="richard_fr3_joint8" type="fixed">
    <origin rpy="0 0 0" xyz="0 0 0.107"/>
    <parent link="richard_fr3_link7"/>
    <child link="richard_fr3_link8"/>
  </joint>
  <!-- New end-effector -->
  <!-- <link name="${prefix}EE">
      <visual name="${prefix}EE_visual">
        <geometry>
          <mesh filename="package://${description_pkg}/meshes/robot_ee/${ee_id}/visual/EE.dae" />
        </geometry>
      </visual>
      <collision name="${prefix}EE_collision">
        <geometry>
          <mesh filename="package://franka_description/meshes/robot_ee/${ee_id}/collision/EE.stl" />
        </geometry>
      </collision>
      <xacro:ee-inertials name="EE" />
    </link> -->
  <!-- <joint name="${prefix}jointEE" type="fixed">
      <origin rpy="0.0 0.0 0.0" xyz="0.0 0.0 0.0" />
      <parent link="${prefix}link8" />
      <child link="${prefix}linkEE" />
    </joint> -->
  <!-- Gazebo requires a joint to a link called "world" for statically mounted robots -->
  <!-- <xacro:if value="${parent == 'world'}">
          <link name="${parent}" />
        </xacro:if> -->
  <!-- <link name="${parent}" /> -->
  <joint name="richard_fr3_base_joint" type="fixed">
    <origin rpy="0 0 0" xyz="0 0 0"/>
    <parent link="richard_fr3_base"/>
    <child link="richard_fr3_link0"/>
  </joint>
  <gazebo reference="richard_fr3_joint1">
    <!-- Needed for ODE to output external wrenches on joints -->
    <provideFeedback>true</provideFeedback>
  </gazebo>
  <transmission name="richard_fr3_joint1_transmission">
    <type>transmission_interface/SimpleTransmission</type>
    <joint name="richard_fr3_joint1">
      <hardwareInterface>hardware_interface/PositionJointInterface</hardwareInterface>
    </joint>
    <actuator name="richard_fr3_joint1_motor">
      <hardwareInterface>hardware_interface/PositionJointInterface</hardwareInterface>
    </actuator>
  </transmission>
  <gazebo reference="richard_fr3_joint2">
    <!-- Needed for ODE to output external wrenches on joints -->
    <provideFeedback>true</provideFeedback>
  </gazebo>
  <transmission name="richard_fr3_joint2_transmission">
    <type>transmission_interface/SimpleTransmission</type>
    <joint name="richard_fr3_joint2">
      <hardwareInterface>hardware_interface/PositionJointInterface</hardwareInterface>
    </joint>
    <actuator name="richard_fr3_joint2_motor">
      <hardwareInterface>hardware_interface/PositionJointInterface</hardwareInterface>
    </actuator>
  </transmission>
  <gazebo reference="richard_fr3_joint3">
    <!-- Needed for ODE to output external wrenches on joints -->
    <provideFeedback>true</provideFeedback>
  </gazebo>
  <transmission name="richard_fr3_joint3_transmission">
    <type>transmission_interface/SimpleTransmission</type>
    <joint name="richard_fr3_joint3">
      <hardwareInterface>hardware_interface/PositionJointInterface</hardwareInterface>
    </joint>
    <actuator name="richard_fr3_joint3_motor">
      <hardwareInterface>hardware_interface/PositionJointInterface</hardwareInterface>
    </actuator>
  </transmission>
  <gazebo reference="richard_fr3_joint4">
    <!-- Needed for ODE to output external wrenches on joints -->
    <provideFeedback>true</provideFeedback>
  </gazebo>
  <transmission name="richard_fr3_joint4_transmission">
    <type>transmission_interface/SimpleTransmission</type>
    <joint name="richard_fr3_joint4">
      <hardwareInterface>hardware_interface/PositionJointInterface</hardwareInterface>
    </joint>
    <actuator name="richard_fr3_joint4_motor">
      <hardwareInterface>hardware_interface/PositionJointInterface</hardwareInterface>
    </actuator>
  </transmission>
  <gazebo reference="richard_fr3_joint5">
    <!-- Needed for ODE to output external wrenches on joints -->
    <provideFeedback>true</provideFeedback>
  </gazebo>
  <transmission name="richard_fr3_joint5_transmission">
    <type>transmission_interface/SimpleTransmission</type>
    <joint name="richard_fr3_joint5">
      <hardwareInterface>hardware_interface/PositionJointInterface</hardwareInterface>
    </joint>
    <actuator name="richard_fr3_joint5_motor">
      <hardwareInterface>hardware_interface/PositionJointInterface</hardwareInterface>
    </actuator>
  </transmission>
  <gazebo reference="richard_fr3_joint6">
    <!-- Needed for ODE to output external wrenches on joints -->
    <provideFeedback>true</provideFeedback>
  </gazebo>
  <transmission name="richard_fr3_joint6_transmission">
    <type>transmission_interface/SimpleTransmission</type>
    <joint name="richard_fr3_joint6">
      <hardwareInterface>hardware_interface/PositionJointInterface</hardwareInterface>
    </joint>
    <actuator name="richard_fr3_joint6_motor">
      <hardwareInterface>hardware_interface/PositionJointInterface</hardwareInterface>
    </actuator>
  </transmission>
  <gazebo reference="richard_fr3_joint7">
    <!-- Needed for ODE to output external wrenches on joints -->
    <provideFeedback>true</provideFeedback>
  </gazebo>
  <transmission name="richard_fr3_joint7_transmission">
    <type>transmission_interface/SimpleTransmission</type>
    <joint name="richard_fr3_joint7">
      <hardwareInterface>hardware_interface/PositionJointInterface</hardwareInterface>
    </joint>
    <actuator name="richard_fr3_joint7_motor">
      <hardwareInterface>hardware_interface/PositionJointInterface</hardwareInterface>
    </actuator>
  </transmission>
  <gazebo reference="richard_fr3_joint1">
    <!-- Needed for ODE to output external wrenches on joints -->
    <provideFeedback>true</provideFeedback>
  </gazebo>
  <transmission name="richard_fr3_joint1_transmission">
    <type>transmission_interface/SimpleTransmission</type>
    <joint name="richard_fr3_joint1">
      <hardwareInterface>hardware_interface/VelocityJointInterface</hardwareInterface>
    </joint>
    <actuator name="richard_fr3_joint1_motor">
      <hardwareInterface>hardware_interface/VelocityJointInterface</hardwareInterface>
    </actuator>
  </transmission>
  <gazebo reference="richard_fr3_joint2">
    <!-- Needed for ODE to output external wrenches on joints -->
    <provideFeedback>true</provideFeedback>
  </gazebo>
  <transmission name="richard_fr3_joint2_transmission">
    <type>transmission_interface/SimpleTransmission</type>
    <joint name="richard_fr3_joint2">
      <hardwareInterface>hardware_interface/VelocityJointInterface</hardwareInterface>
    </joint>
    <actuator name="richard_fr3_joint2_motor">
      <hardwareInterface>hardware_interface/VelocityJointInterface</hardwareInterface>
    </actuator>
  </transmission>
  <gazebo reference="richard_fr3_joint3">
    <!-- Needed for ODE to output external wrenches on joints -->
    <provideFeedback>true</provideFeedback>
  </gazebo>
  <transmission name="richard_fr3_joint3_transmission">
    <type>transmission_interface/SimpleTransmission</type>
    <joint name="richard_fr3_joint3">
      <hardwareInterface>hardware_interface/VelocityJointInterface</hardwareInterface>
    </joint>
    <actuator name="richard_fr3_joint3_motor">
      <hardwareInterface>hardware_interface/VelocityJointInterface</hardwareInterface>
    </actuator>
  </transmission>
  <gazebo reference="richard_fr3_joint4">
    <!-- Needed for ODE to output external wrenches on joints -->
    <provideFeedback>true</provideFeedback>
  </gazebo>
  <transmission name="richard_fr3_joint4_transmission">
    <type>transmission_interface/SimpleTransmission</type>
    <joint name="richard_fr3_joint4">
      <hardwareInterface>hardware_interface/VelocityJointInterface</hardwareInterface>
    </joint>
    <actuator name="richard_fr3_joint4_motor">
      <hardwareInterface>hardware_interface/VelocityJointInterface</hardwareInterface>
    </actuator>
  </transmission>
  <gazebo reference="richard_fr3_joint5">
    <!-- Needed for ODE to output external wrenches on joints -->
    <provideFeedback>true</provideFeedback>
  </gazebo>
  <transmission name="richard_fr3_joint5_transmission">
    <type>transmission_interface/SimpleTransmission</type>
    <joint name="richard_fr3_joint5">
      <hardwareInterface>hardware_interface/VelocityJointInterface</hardwareInterface>
    </joint>
    <actuator name="richard_fr3_joint5_motor">
      <hardwareInterface>hardware_interface/VelocityJointInterface</hardwareInterface>
    </actuator>
  </transmission>
  <gazebo reference="richard_fr3_joint6">
    <!-- Needed for ODE to output external wrenches on joints -->
    <provideFeedback>true</provideFeedback>
  </gazebo>
  <transmission name="richard_fr3_joint6_transmission">
    <type>transmission_interface/SimpleTransmission</type>
    <joint name="richard_fr3_joint6">
      <hardwareInterface>hardware_interface/VelocityJointInterface</hardwareInterface>
    </joint>
    <actuator name="richard_fr3_joint6_motor">
      <hardwareInterface>hardware_interface/VelocityJointInterface</hardwareInterface>
    </actuator>
  </transmission>
  <gazebo reference="richard_fr3_joint7">
    <!-- Needed for ODE to output external wrenches on joints -->
    <provideFeedback>true</provideFeedback>
  </gazebo>
  <transmission name="richard_fr3_joint7_transmission">
    <type>transmission_interface/SimpleTransmission</type>
    <joint name="richard_fr3_joint7">
      <hardwareInterface>hardware_interface/VelocityJointInterface</hardwareInterface>
    </joint>
    <actuator name="richard_fr3_joint7_motor">
      <hardwareInterface>hardware_interface/VelocityJointInterface</hardwareInterface>
    </actuator>
  </transmission>
  <gazebo reference="richard_fr3_joint1">
    <!-- Needed for ODE to output external wrenches on joints -->
    <provideFeedback>true</provideFeedback>
  </gazebo>
  <transmission name="richard_fr3_joint1_transmission">
    <type>transmission_interface/SimpleTransmission</type>
    <joint name="richard_fr3_joint1">
      <hardwareInterface>hardware_interface/EffortJointInterface</hardwareInterface>
    </joint>
    <actuator name="richard_fr3_joint1_motor">
      <hardwareInterface>hardware_interface/EffortJointInterface</hardwareInterface>
    </actuator>
  </transmission>
  <gazebo reference="richard_fr3_joint2">
    <!-- Needed for ODE to output external wrenches on joints -->
    <provideFeedback>true</provideFeedback>
  </gazebo>
  <transmission name="richard_fr3_joint2_transmission">
    <type>transmission_interface/SimpleTransmission</type>
    <joint name="richard_fr3_joint2">
      <hardwareInterface>hardware_interface/EffortJointInterface</hardwareInterface>
    </joint>
    <actuator name="richard_fr3_joint2_motor">
      <hardwareInterface>hardware_interface/EffortJointInterface</hardwareInterface>
    </actuator>
  </transmission>
  <gazebo reference="richard_fr3_joint3">
    <!-- Needed for ODE to output external wrenches on joints -->
    <provideFeedback>true</provideFeedback>
  </gazebo>
  <transmission name="richard_fr3_joint3_transmission">
    <type>transmission_interface/SimpleTransmission</type>
    <joint name="richard_fr3_joint3">
      <hardwareInterface>hardware_interface/EffortJointInterface</hardwareInterface>
    </joint>
    <actuator name="richard_fr3_joint3_motor">
      <hardwareInterface>hardware_interface/EffortJointInterface</hardwareInterface>
    </actuator>
  </transmission>
  <gazebo reference="richard_fr3_joint4">
    <!-- Needed for ODE to output external wrenches on joints -->
    <provideFeedback>true</provideFeedback>
  </gazebo>
  <transmission name="richard_fr3_joint4_transmission">
    <type>transmission_interface/SimpleTransmission</type>
    <joint name="richard_fr3_joint4">
      <hardwareInterface>hardware_interface/EffortJointInterface</hardwareInterface>
    </joint>
    <actuator name="richard_fr3_joint4_motor">
      <hardwareInterface>hardware_interface/EffortJointInterface</hardwareInterface>
    </actuator>
  </transmission>
  <gazebo reference="richard_fr3_joint5">
    <!-- Needed for ODE to output external wrenches on joints -->
    <provideFeedback>true</provideFeedback>
  </gazebo>
  <transmission name="richard_fr3_joint5_transmission">
    <type>transmission_interface/SimpleTransmission</type>
    <joint name="richard_fr3_joint5">
      <hardwareInterface>hardware_interface/EffortJointInterface</hardwareInterface>
    </joint>
    <actuator name="richard_fr3_joint5_motor">
      <hardwareInterface>hardware_interface/EffortJointInterface</hardwareInterface>
    </actuator>
  </transmission>
  <gazebo reference="richard_fr3_joint6">
    <!-- Needed for ODE to output external wrenches on joints -->
    <provideFeedback>true</provideFeedback>
  </gazebo>
  <transmission name="richard_fr3_joint6_transmission">
    <type>transmission_interface/SimpleTransmission</type>
    <joint name="richard_fr3_joint6">
      <hardwareInterface>hardware_interface/EffortJointInterface</hardwareInterface>
    </joint>
    <actuator name="richard_fr3_joint6_motor">
      <hardwareInterface>hardware_interface/EffortJointInterface</hardwareInterface>
    </actuator>
  </transmission>
  <gazebo reference="richard_fr3_joint7">
    <!-- Needed for ODE to output external wrenches on joints -->
    <provideFeedback>true</provideFeedback>
  </gazebo>
  <transmission name="richard_fr3_joint7_transmission">
    <type>transmission_interface/SimpleTransmission</type>
    <joint name="richard_fr3_joint7">
      <hardwareInterface>hardware_interface/EffortJointInterface</hardwareInterface>
    </joint>
    <actuator name="richard_fr3_joint7_motor">
      <hardwareInterface>hardware_interface/EffortJointInterface</hardwareInterface>
    </actuator>
  </transmission>
  <transmission name="richardrichard_fr3__franka_state">
    <type>franka_hw/FrankaStateInterface</type>
    <joint name="richardrichard_fr3__joint1">
      <hardwareInterface>franka_hw/FrankaStateInterface</hardwareInterface>
    </joint>
    <joint name="richardrichard_fr3__joint2">
      <hardwareInterface>franka_hw/FrankaStateInterface</hardwareInterface>
    </joint>
    <joint name="richardrichard_fr3__joint3">
      <hardwareInterface>franka_hw/FrankaStateInterface</hardwareInterface>
    </joint>
    <joint name="richardrichard_fr3__joint4">
      <hardwareInterface>franka_hw/FrankaStateInterface</hardwareInterface>
    </joint>
    <joint name="richardrichard_fr3__joint5">
      <hardwareInterface>franka_hw/FrankaStateInterface</hardwareInterface>
    </joint>
    <joint name="richardrichard_fr3__joint6">
      <hardwareInterface>franka_hw/FrankaStateInterface</hardwareInterface>
    </joint>
    <joint name="richardrichard_fr3__joint7">
      <hardwareInterface>franka_hw/FrankaStateInterface</hardwareInterface>
    </joint>
    <actuator name="richardrichard_fr3__motor1">
      <hardwareInterface>franka_hw/FrankaStateInterface</hardwareInterface>
    </actuator>
    <actuator name="richardrichard_fr3__motor2">
      <hardwareInterface>franka_hw/FrankaStateInterface</hardwareInterface>
    </actuator>
    <actuator name="richardrichard_fr3__motor3">
      <hardwareInterface>franka_hw/FrankaStateInterface</hardwareInterface>
    </actuator>
    <actuator name="richardrichard_fr3__motor4">
      <hardwareInterface>franka_hw/FrankaStateInterface</hardwareInterface>
    </actuator>
    <actuator name="richardrichard_fr3__motor5">
      <hardwareInterface>franka_hw/FrankaStateInterface</hardwareInterface>
    </actuator>
    <actuator name="richardrichard_fr3__motor6">
      <hardwareInterface>franka_hw/FrankaStateInterface</hardwareInterface>
    </actuator>
    <actuator name="richardrichard_fr3__motor7">
      <hardwareInterface>franka_hw/FrankaStateInterface</hardwareInterface>
    </actuator>
  </transmission>
  <transmission name="richardrichard_fr3__franka_model">
    <type>franka_hw/FrankaModelInterface</type>
    <joint name="richard_fr3_joint1">
      <role>root</role>
      <hardwareInterface>franka_hw/FrankaModelInterface</hardwareInterface>
    </joint>
    <joint name="richard_fr3_joint8">
      <role>tip</role>
      <hardwareInterface>franka_hw/FrankaModelInterface</hardwareInterface>
    </joint>
    <actuator name="richard_fr3_joint1_motor_root">
      <hardwareInterface>franka_hw/FrankaModelInterface</hardwareInterface>
    </actuator>
    <actuator name="richard_fr3_joint8_motor_tip">
      <hardwareInterface>franka_hw/FrankaModelInterface</hardwareInterface>
    </actuator>
  </transmission>
  <!-- left arm -->
  <ros2_control name="lewis_FrankaHardwareInterface" type="system">
    <hardware>
      <param name="version">0.1.0</param>
      <param name="arm_id">fr3</param>
      <param name="arm_prefix">lewis</param>
      <plugin>mujoco_ros2_control/MujocoSystem</plugin>
    </hardware>
    <joint name="lewis_fr3_joint1">
      <!-- Command Interfaces -->
      <command_interface name="effort"/>
      <!-- State Interfaces -->
      <state_interface name="position">
        <param name="initial_value">0.0</param>
      </state_interface>
      <state_interface name="velocity">
        <param name="initial_value">0.0</param>
      </state_interface>
      <state_interface name="effort">
        <param name="initial_value">-1.2</param>
      </state_interface>
    </joint>
    <joint name="lewis_fr3_joint2">
      <!-- Command Interfaces -->
      <command_interface name="effort"/>
      <!-- State Interfaces -->
      <state_interface name="position">
        <param name="initial_value">-0.7853981633974483</param>
      </state_interface>
      <state_interface name="velocity">
        <param name="initial_value">0.0</param>
      </state_interface>
      <state_interface name="effort">
        <param name="initial_value">-6.6</param>
      </state_interface>
    </joint>
    <joint name="lewis_fr3_joint3">
      <!-- Command Interfaces -->
      <command_interface name="effort"/>
      <!-- State Interfaces -->
      <state_interface name="position">
        <param name="initial_value">0.0</param>
      </state_interface>
      <state_interface name="velocity">
        <param name="initial_value">0.0</param>
      </state_interface>
      <state_interface name="effort">
        <param name="initial_value">-18.339</param>
      </state_interface>
    </joint>
    <joint name="lewis_fr3_joint4">
      <!-- Command Interfaces -->
      <command_interface name="effort"/>
      <!-- State Interfaces -->
      <state_interface name="position">
        <param name="initial_value">-2.356194490192345</param>
      </state_interface>
      <state_interface name="velocity">
        <param name="initial_value">0.0</param>
      </state_interface>
      <state_interface name="effort">
        <param name="initial_value">12.383</param>
      </state_interface>
    </joint>
    <joint name="lewis_fr3_joint5">
      <!-- Command Interfaces -->
      <command_interface name="effort"/>
      <!-- State Interfaces -->
      <state_interface name="position">
        <param name="initial_value">0.0</param>
      </state_interface>
      <state_interface name="velocity">
        <param name="initial_value">0.0</param>
      </state_interface>
      <state_interface name="effort">
        <param name="initial_value">0.0255</param>
      </state_interface>
    </joint>
    <joint name="lewis_fr3_joint6">
      <!-- Command Interfaces -->
      <command_interface name="effort"/>
      <!-- State Interfaces -->
      <state_interface name="position">
        <param name="initial_value">1.5707963267948966</param>
      </state_interface>
      <state_interface name="velocity">
        <param name="initial_value">0.0</param>
      </state_interface>
      <state_interface name="effort">
        <param name="initial_value">0.86038</param>
      </state_interface>
    </joint>
    <joint name="lewis_fr3_joint7">
      <!-- Command Interfaces -->
      <command_interface name="effort"/>
      <!-- State Interfaces -->
      <state_interface name="position">
        <param name="initial_value">0.7853981633974483</param>
      </state_interface>
      <state_interface name="velocity">
        <param name="initial_value">0.0</param>
      </state_interface>
      <state_interface name="effort">
        <param name="initial_value">-0.0036</param>
      </state_interface>
    </joint>
  </ros2_control>

  <!-- right arm -->
  <ros2_control name="richard_FrankaHardwareInterface" type="system">
    <hardware>
      <param name="version">0.1.0</param>
      <param name="arm_id">fr3</param>
      <param name="arm_prefix">richard</param>
      <plugin>mujoco_ros2_control/MujocoSystem</plugin>
    </hardware>
    <joint name="richard_fr3_joint1">
      <!-- Command Interfaces -->
      <command_interface name="effort"/>
      <!-- State Interfaces -->
      <state_interface name="position">
        <param name="initial_value">0.0</param>
      </state_interface>
      <state_interface name="velocity">
        <param name="initial_value">0.0</param>
      </state_interface>
      <state_interface name="effort">
        <param name="initial_value">1.43011</param>
      </state_interface>
    </joint>
    <joint name="richard_fr3_joint2">
      <!-- Command Interfaces -->
      <command_interface name="effort"/>
      <!-- State Interfaces -->
      <state_interface name="position">
        <param name="initial_value">-0.7853981633974483</param>
      </state_interface>
      <state_interface name="velocity">
        <param name="initial_value">0.0</param>
      </state_interface>
      <state_interface name="effort">
        <param name="initial_value">-6.6</param>
      </state_interface>
    </joint>
    <joint name="richard_fr3_joint3">
      <!-- Command Interfaces -->
      <command_interface name="effort"/>
      <!-- State Interfaces -->
      <state_interface name="position">
        <param name="initial_value">0.0</param>
      </state_interface>
      <state_interface name="velocity">
        <param name="initial_value">0.0</param>
      </state_interface>
      <state_interface name="effort">
        <param name="initial_value">17.782249</param>
      </state_interface>
    </joint>
    <joint name="richard_fr3_joint4">
      <!-- Command Interfaces -->
      <command_interface name="effort"/>  
      <!-- State Interfaces -->
      <state_interface name="position">
        <param name="initial_value">-2.356194490192345</param>
      </state_interface>
      <state_interface name="velocity">
        <param name="initial_value">0.0</param>
      </state_interface>
      <state_interface name="effort">
        <param name="initial_value">12.383</param>
      </state_interface>
    </joint>
    <joint name="richard_fr3_joint5">
      <!-- Command Interfaces -->
      <command_interface name="effort"/>
      <!-- State Interfaces -->
      <state_interface name="position">
        <param name="initial_value">0.0</param>
      </state_interface>
      <state_interface name="velocity">
        <param name="initial_value">0.0</param>
      </state_interface>
      <state_interface name="effort">
        <param name="initial_value">0.943589</param>
      </state_interface>
    </joint>
    <joint name="richard_fr3_joint6">
      <!-- Command Interfaces -->
      <command_interface name="effort"/>
        <!-- State Interfaces -->
      <state_interface name="position">
        <param name="initial_value">1.5707963267948966</param>
      </state_interface>
      <state_interface name="velocity">
        <param name="initial_value">0.0</param>
      </state_interface>
      <state_interface name="effort">
        <param name="initial_value">0.86038</param>
      </state_interface>
    </joint>
    <joint name="richard_fr3_joint7">
      <!-- Command Interfaces -->
      <command_interface name="effort"/>
      <!-- State Interfaces -->
      <state_interface name="position">
        <param name="initial_value">0.7853981633974483</param>
      </state_interface>
      <state_interface name="velocity">
        <param name="initial_value">0.0</param>
      </state_interface>
      <state_interface name="effort">
        <param name="initial_value">-0.023839</param>
      </state_interface>
    </joint>
  </ros2_control>

  <!-- base -->
  <ros2_control name="base_JointHardwareInterface" type="system">
    <hardware>
      <plugin>mujoco_ros2_control/MujocoSystem</plugin>
    </hardware>
    <joint name="base_joint">
      <command_interface name="effort"/> 
      <state_interface name="position">
        <param name="initial_value">0.0</param>
      </state_interface>
      <state_interface name="velocity">
        <param name="initial_value">0.0</param>
      </state_interface>
      <state_interface name="effort">
        <param name="initial_value">0.0</param>
      </state_interface>
    </joint>
  </ros2_control>

  <!-- <ros2_control name="base_HardwareInterface" type="system">
    <hardware>
      <plugin>gz_ros2_control/GazeboSimSystem</plugin>
    </hardware>
    <joint name="base_joint">
      <gazebo>
        <hardwareInterface>EffortJointInterface</hardwareInterface>
        <provideFeedback>true</provideFeedback>
      </gazebo>
      <command_interface name="effort"/>
      <state_interface name="position">
        <param name="initial_value">0.0</param>
      </state_interface>
      <state_interface name="velocity">
        <param name="initial_value">0.0</param>
      </state_interface>
      <state_interface name="effort">
        <param name="initial_value">0.0</param>
      </state_interface>
    </joint>
  </ros2_control> -->

  <!-- <gazebo>
    <plugin filename="libgz_ros2_control-system.so" name="gz_ros2_control::GazeboSimROS2ControlPlugin">
      <robot_param>robot_description</robot_param>
      <robot_param_node>robot_state_publisher</robot_param_node>
      <controller_manager_name>controller_manager</controller_manager_name>
      <parameters>/root/ros2_ws/install/bifrank_control/share/bifrank_control/config/bifrank_controllers.yaml</parameters>
    </plugin>
  </gazebo> -->

</robot>
